<?xml version="1.0"?>
<robot>

    <link name="gripper_link">
        <visual>
            <geometry>
                <mesh filename="file://$(find kr210_description)/meshes/gripper/gripper_base.dae"/>
            </geometry>
            <origin xyz="0 0 0" rpy="0 0 0"/>
        </visual>

        <collision>
            <geometry>
                <mesh filename="file://$(find kr210_description)/meshes/gripper/gripper_base.dae"/>
            </geometry>
            <origin xyz="0 0 0" rpy="0 0 0"/>
        </collision>

        <inertial>
            <mass value="${gripper_mass}"/>
            <origin xyz="0 0 0" rpy="0 0 0"/>
            <inertia ixx="0.0001" ixy="0" ixz="0" iyy="0.0002" iyz="0" izz="0.0001"/>
        </inertial>
    </link>

    <link name="right_finger_link">
        <visual>
            <geometry>
                <mesh filename="file://$(find kr210_description)/meshes/gripper/finger_right.dae"/>
            </geometry>
            <origin xyz="0 0 0" rpy="0 0 0"/>
        </visual>

        <collision>
            <geometry>
                <mesh filename="file://$(find kr210_description)/meshes/gripper/finger_right_collision.dae"/>
            </geometry>
            <origin xyz="0 0 0" rpy="0 0 0"/>
        </collision>

        <inertial>
            <mass value="${finger_mass}"/>
            <origin xyz="0 0 0" rpy="0 0 0"/>
            <inertia ixx="0.002" ixy="0" ixz="0" iyy="0.0002" iyz="0" izz="0.0002"/>
        </inertial>

    </link>

    <link name="left_finger_link">
        <visual>
            <geometry>
                <mesh filename="file://$(find kr210_description)/meshes/gripper/finger_left.dae"/>
            </geometry>
            <origin xyz="0 0 0" rpy="0 0 0"/>
        </visual>

        <collision>
            <geometry>
                <mesh filename="file://$(find kr210_description)/meshes/gripper/finger_left_collision.dae"/>
            </geometry>
            <origin xyz="0 0 0" rpy="0 0 0"/>
        </collision>

        <inertial>
            <mass value="${finger_mass}"/>
            <origin xyz="0 0 0" rpy="0 0 0"/>
            <inertia ixx="0.002" ixy="0" ixz="0" iyy="0.0002" iyz="0" izz="0.0002"/>
        </inertial>
    </link>

    <joint name="gripper_joint" type="fixed">
        <parent link="link_6"/>
        <child link="gripper_link"/>
        <origin xyz="0.11 0 0" rpy="0 0 0"/>
    </joint>

    <joint name="gripper_right_finger_joint" type="prismatic">
        <parent link="gripper_link"/>
        <child link="right_finger_link"/>
        <origin xyz="0.15 -0.0725 0" rpy="0 0 0"/>
        <axis xyz="0 1 0"/>
        <limit effort="100" lower="-0.01" upper="0.06" velocity="0.05"/>
        <dynamics damping="0.7"/>
    </joint>

    <joint name="gripper_left_finger_joint" type="prismatic">
        <parent link="gripper_link"/>
        <child link="left_finger_link"/>
        <origin xyz="0.15 0.0725 0" rpy="0 0 0"/>
        <axis xyz="0 -1 0"/>
        <limit effort="100" lower="-0.01" upper="0.06" velocity="0.05"/>
        <dynamics damping="0.7"/>
    </joint>
</robot>